Workbook
Name _Fill: [1]cotiz1!#REF!
Name _Order1: 255
Name _Order2: 255
Name A: [2]ALMAGRO!#REF!
Name AAA: {#N/A,#N/A,FALSE,"Aging Summary";#N/A,#N/A,FALSE,"Ratio Analysis";#N/A,#N/A,FALSE,"Test 120 Day Accts";#N/A,#N/A,FALSE,"Tickmarks"}
Name AAA: {#N/A,#N/A,FALSE,"Aging Summary";#N/A,#N/A,FALSE,"Ratio Analysis";#N/A,#N/A,FALSE,"Test 120 Day Accts";#N/A,#N/A,FALSE,"Tickmarks"}
Name AAA: {#N/A,#N/A,FALSE,"Aging Summary";#N/A,#N/A,FALSE,"Ratio Analysis";#N/A,#N/A,FALSE,"Test 120 Day Accts";#N/A,#N/A,FALSE,"Tickmarks"}
Name abr_14: [3]TablaCM!$B$23:$N$23
Name ac: {#N/A,#N/A,FALSE,"1209004";#N/A,#N/A,FALSE,"1209004"}
Name ac: {#N/A,#N/A,FALSE,"1209004";#N/A,#N/A,FALSE,"1209004"}
Name ac: {#N/A,#N/A,FALSE,"1209004";#N/A,#N/A,FALSE,"1209004"}
Name ac: {#N/A,#N/A,FALSE,"1209004";#N/A,#N/A,FALSE,"1209004"}
Name ac: {#N/A,#N/A,FALSE,"1209004";#N/A,#N/A,FALSE,"1209004"}
Name Ago_14: [3]TablaCM!$B$27:$N$27
Name AP: {#N/A,#N/A,FALSE,"Aging Summary";#N/A,#N/A,FALSE,"Ratio Analysis";#N/A,#N/A,FALSE,"Test 120 Day Accts";#N/A,#N/A,FALSE,"Tickmarks"}
Name AP: {#N/A,#N/A,FALSE,"Aging Summary";#N/A,#N/A,FALSE,"Ratio Analysis";#N/A,#N/A,FALSE,"Test 120 Day Accts";#N/A,#N/A,FALSE,"Tickmarks"}
Name AP: {#N/A,#N/A,FALSE,"Aging Summary";#N/A,#N/A,FALSE,"Ratio Analysis";#N/A,#N/A,FALSE,"Test 120 Day Accts";#N/A,#N/A,FALSE,"Tickmarks"}
Name AP: {#N/A,#N/A,FALSE,"Aging Summary";#N/A,#N/A,FALSE,"Ratio Analysis";#N/A,#N/A,FALSE,"Test 120 Day Accts";#N/A,#N/A,FALSE,"Tickmarks"}
Name AP: {#N/A,#N/A,FALSE,"Aging Summary";#N/A,#N/A,FALSE,"Ratio Analysis";#N/A,#N/A,FALSE,"Test 120 Day Accts";#N/A,#N/A,FALSE,"Tickmarks"}
Name AS2DocOpenMode: "AS2DocumentEdit"
Name B: [2]ALMAGRO!#REF!
Name CIStgoCosa: [4]C24_22!$A$1:$L$49
Name Ctapers: [5]CtaVrs24!#REF!
Name CTAPPAG: '[6]21-05'!#REF!
Name dd: {#N/A,#N/A,FALSE,"Aging Summary";#N/A,#N/A,FALSE,"Ratio Analysis";#N/A,#N/A,FALSE,"Test 120 Day Accts";#N/A,#N/A,FALSE,"Tickmarks"}
Name dd: {#N/A,#N/A,FALSE,"Aging Summary";#N/A,#N/A,FALSE,"Ratio Analysis";#N/A,#N/A,FALSE,"Test 120 Day Accts";#N/A,#N/A,FALSE,"Tickmarks"}
Name dd: {#N/A,#N/A,FALSE,"Aging Summary";#N/A,#N/A,FALSE,"Ratio Analysis";#N/A,#N/A,FALSE,"Test 120 Day Accts";#N/A,#N/A,FALSE,"Tickmarks"}
Name dd: {#N/A,#N/A,FALSE,"Aging Summary";#N/A,#N/A,FALSE,"Ratio Analysis";#N/A,#N/A,FALSE,"Test 120 Day Accts";#N/A,#N/A,FALSE,"Tickmarks"}
Name dd: {#N/A,#N/A,FALSE,"Aging Summary";#N/A,#N/A,FALSE,"Ratio Analysis";#N/A,#N/A,FALSE,"Test 120 Day Accts";#N/A,#N/A,FALSE,"Tickmarks"}
Name Dic_14: [3]TablaCM!$B$31:$N$31
Name DiciembreIFRS2008: {#N/A,#N/A,FALSE,"Aging Summary";#N/A,#N/A,FALSE,"Ratio Analysis";#N/A,#N/A,FALSE,"Test 120 Day Accts";#N/A,#N/A,FALSE,"Tickmarks"}
Name DiciembreIFRS2008: {#N/A,#N/A,FALSE,"Aging Summary";#N/A,#N/A,FALSE,"Ratio Analysis";#N/A,#N/A,FALSE,"Test 120 Day Accts";#N/A,#N/A,FALSE,"Tickmarks"}
Name DiciembreIFRS2008: {#N/A,#N/A,FALSE,"Aging Summary";#N/A,#N/A,FALSE,"Ratio Analysis";#N/A,#N/A,FALSE,"Test 120 Day Accts";#N/A,#N/A,FALSE,"Tickmarks"}
Name DiciembreIFRS2008: {#N/A,#N/A,FALSE,"Aging Summary";#N/A,#N/A,FALSE,"Ratio Analysis";#N/A,#N/A,FALSE,"Test 120 Day Accts";#N/A,#N/A,FALSE,"Tickmarks"}
Name DiciembreIFRS2008: {#N/A,#N/A,FALSE,"Aging Summary";#N/A,#N/A,FALSE,"Ratio Analysis";#N/A,#N/A,FALSE,"Test 120 Day Accts";#N/A,#N/A,FALSE,"Tickmarks"}
Name dsar: {#N/A,#N/A,FALSE,"Aging Summary";#N/A,#N/A,FALSE,"Ratio Analysis";#N/A,#N/A,FALSE,"Test 120 Day Accts";#N/A,#N/A,FALSE,"Tickmarks"}
Name dsar: {#N/A,#N/A,FALSE,"Aging Summary";#N/A,#N/A,FALSE,"Ratio Analysis";#N/A,#N/A,FALSE,"Test 120 Day Accts";#N/A,#N/A,FALSE,"Tickmarks"}
Name dsar: {#N/A,#N/A,FALSE,"Aging Summary";#N/A,#N/A,FALSE,"Ratio Analysis";#N/A,#N/A,FALSE,"Test 120 Day Accts";#N/A,#N/A,FALSE,"Tickmarks"}
Name dsar: {#N/A,#N/A,FALSE,"Aging Summary";#N/A,#N/A,FALSE,"Ratio Analysis";#N/A,#N/A,FALSE,"Test 120 Day Accts";#N/A,#N/A,FALSE,"Tickmarks"}
Name dsar: {#N/A,#N/A,FALSE,"Aging Summary";#N/A,#N/A,FALSE,"Ratio Analysis";#N/A,#N/A,FALSE,"Test 120 Day Accts";#N/A,#N/A,FALSE,"Tickmarks"}
Name e: [7]Drivers!$B$14
Name ergdagd: {#N/A,#N/A,FALSE,"Aging Summary";#N/A,#N/A,FALSE,"Ratio Analysis";#N/A,#N/A,FALSE,"Test 120 Day Accts";#N/A,#N/A,FALSE,"Tickmarks"}
Name ergdagd: {#N/A,#N/A,FALSE,"Aging Summary";#N/A,#N/A,FALSE,"Ratio Analysis";#N/A,#N/A,FALSE,"Test 120 Day Accts";#N/A,#N/A,FALSE,"Tickmarks"}
Name ergdagd: {#N/A,#N/A,FALSE,"Aging Summary";#N/A,#N/A,FALSE,"Ratio Analysis";#N/A,#N/A,FALSE,"Test 120 Day Accts";#N/A,#N/A,FALSE,"Tickmarks"}
Name ergdagd: {#N/A,#N/A,FALSE,"Aging Summary";#N/A,#N/A,FALSE,"Ratio Analysis";#N/A,#N/A,FALSE,"Test 120 Day Accts";#N/A,#N/A,FALSE,"Tickmarks"}
Name ergdagd: {#N/A,#N/A,FALSE,"Aging Summary";#N/A,#N/A,FALSE,"Ratio Analysis";#N/A,#N/A,FALSE,"Test 120 Day Accts";#N/A,#N/A,FALSE,"Tickmarks"}
Name erwrr: {#N/A,#N/A,FALSE,"Aging Summary";#N/A,#N/A,FALSE,"Ratio Analysis";#N/A,#N/A,FALSE,"Test 120 Day Accts";#N/A,#N/A,FALSE,"Tickmarks"}
Name erwrr: {#N/A,#N/A,FALSE,"Aging Summary";#N/A,#N/A,FALSE,"Ratio Analysis";#N/A,#N/A,FALSE,"Test 120 Day Accts";#N/A,#N/A,FALSE,"Tickmarks"}
Name erwrr: {#N/A,#N/A,FALSE,"Aging Summary";#N/A,#N/A,FALSE,"Ratio Analysis";#N/A,#N/A,FALSE,"Test 120 Day Accts";#N/A,#N/A,FALSE,"Tickmarks"}
Name erwrr: {#N/A,#N/A,FALSE,"Aging Summary";#N/A,#N/A,FALSE,"Ratio Analysis";#N/A,#N/A,FALSE,"Test 120 Day Accts";#N/A,#N/A,FALSE,"Tickmarks"}
Name erwrr: {#N/A,#N/A,FALSE,"Aging Summary";#N/A,#N/A,FALSE,"Ratio Analysis";#N/A,#N/A,FALSE,"Test 120 Day Accts";#N/A,#N/A,FALSE,"Tickmarks"}
Name FactorAbril: [8]TABLA!$E$23
Name FactorJunio: [8]TABLA!$E$25
Name FactorNoviembre: [8]TABLA!$E$30
Name FactorSeptiembre: [8]TABLA!$E$28
Name fg: {#N/A,#N/A,FALSE,"1209004";#N/A,#N/A,FALSE,"1209004"}
Name fg: {#N/A,#N/A,FALSE,"1209004";#N/A,#N/A,FALSE,"1209004"}
Name fg: {#N/A,#N/A,FALSE,"1209004";#N/A,#N/A,FALSE,"1209004"}
Name fg: {#N/A,#N/A,FALSE,"1209004";#N/A,#N/A,FALSE,"1209004"}
Name fg: {#N/A,#N/A,FALSE,"1209004";#N/A,#N/A,FALSE,"1209004"}

Sheet F1948 2023
B5: Declaración Jurada anual sobre retiros, remesas y/o dividendos distribuidos, o cantidades distribuidas a cualquier título y créditos correspondientes, efectuados por contribuyentes sujetos al régimen de la letra A) y al número 3 de la letra D) del artículo 14 de la LIR, y sobre saldo de retiros en exceso pendientes de imputación.
AH6: F1948
B7: Sección A: IDENTIFICACIÓN DEL DECLARANTE | AG7: FOLIO
B9: ROL ÚNICO TRIBUTARIO | D9: NOMBRE O RAZÓN SOCIAL
B11: DOMICILIO | D11: COMUNA
B13: CORREO ELECTRÓNICO | D13: TELÉFONO
B17: Sección B: | C17: ANTECEDENTES DE LOS INFORMADOS (Receptor de los retiros, remesas o dividendos. Persona natural o jurídica)
B18: Fecha del retiro, remesa y/o dividendo distribuido | C18: RUT del Pleno Propietario o Usufructuario receptor del retiro, remesa y/o dividendo distribuido | D18: Usfructuario beneficiario del retiro, remesa y/o dividendo distribuido | E18: Cantidad de acciones al 31/12 | F18: MONTOS DE RETIROS, REMESAS O DIVIDENDOS REAJUSTADOS ($) | R18: CRÉDITOS PARA IMPUESTO GLOBAL COMPLEMENTARIO O ADICIONAL | AG18: Devolución de capital Art.17 N° 7 LIR. | AH18: Número de Certificado
F19: Afectos a los Impuestos Global Complementario y/o Impuesto Adicional | J19: Rentas Exentas e Ingresos No Constitutivos de Renta (REX) | R19: Acumulados a Contar del 01.01.2017 | AA19: Acumulados Hasta el 31.12.2016 | AF19: Crédito por impuesto tasa adicional, Ex. Art. 21 LIR.
J20: Rentas Con Tributación Cumplida | O20: Rentas Exentas | Q20: Ingresos No Constitutivos de Renta | R20: Asociados a Rentas Afectas | X20: Asociados a Rentas Exentas | Z20: Crédito por IPE | AA20: Asociados a Rentas Afectas | AC20: Asociados a Rentas Exentas (artículo 11, Ley 18.401) | AE20: Crédito por IPE
J21: Rentas provenientes del registro RAP y Diferencia Inicial de sociedad acogida al ex Art. 14 TER A) LIR | K21: Otras rentas percibidas Sin Prioridad en su orden de imputación | L21: Exceso Distribuciones Desproporcionadas (N°9 Art.14 A) | M21: Utilidades afectadas con impuesto sustitutivo al FUT (ISFUT) Ley N°20.780 | N21: Rentas generadas hasta el 31.12.1983 y/o utilidades afectadas con impuesto sustitutivo al FUT (ISFUT) LEY N°21.210 | O21: Rentas Exentas de Impuesto Global Complementario (IGC) (Artículo 11, Ley 18.401), Afectas a Impuesto Adicional | P21: Rentas Exentas de Impuesto Global Complementario (IGC) y/o Impuesto Adicional (IA) | R21: No Sujetos a Restitución generados Hasta el 31.12.2019 | T21: No Sujetos a Restitución generados a contar del 01.01.2020 | V21: Sujetos a Restitución | X21: Sujetos a Restitución | AA21: Sin derecho a devolución | AB21: Con derecho a devolución | AC21: Sin derecho a devolución | AD21: Con derecho a devolución | GM21: GERARDO ARTURO ESCUDERO TOLEDO
F22: Con crédito por IDPC generados a contar del 01.01.2017 | G22: Con crédito por IDPC acumulados hasta el 31.12.2016 | H22: Con derecho a crédito por pago de IDPC voluntario | I22: Sin derecho a crédito | R22: Sin derecho a devolución | S22: Con derecho a devolución | T22: Sin derecho a devolución | U22: Con derecho a devolución | V22: Sin derecho a devolución | W22: Con derecho a devolución | X22: Sin derecho a devolución | Y22: Con derecho a devolución
B24: C1 | C24: C2 | D24: C3 | E24: C4 | F24: C5 | G24: C6 | H24: C7 | I24: C8 | J24: C9 | K24: C10 | L24: C11 | M24: C12 | N24: C13 | O24: C14 | P24: C15 | Q24: C16 | R24: C17 | S24: C18 | T24: C19 | U24: C20 | V24: C21 | W24: C22 | X24: C23 | Y24: C24 | Z24: C25 | AA24: C26 | AB24: C27 | AC24: C28 | AD24: C29 | AE24: C30 | AF24: C31 | AG24: C32 | AH24: C33
B25: =+Retiros!C41 -> 45291 | C25: =+Retiros!D41 -> 15640744-5 | E25: =+Retiros!E41 -> 400 | F25: =+Retiros!G41 -> 33034606 | S25: =ROUND(F25*0.111111,0) -> 3670508
B26: =+Retiros!C42 -> 45291 | C26: =+Retiros!D42 -> 16367300-2 | E26: =+Retiros!E42 -> 400 | F26: =+Retiros!G42 -> 33034606 | S26: =ROUND(F26*0.111111,0) -> 3670508
B27: =+Retiros!C43 -> 45291 | C27: =+Retiros!D43 -> 15376982-6 | E27: =+Retiros!E43 -> 200 | F27: =+Retiros!G43 -> 16517303 | S27: =ROUND(F27*0.111111,0) -> 1835254
B31: Sección C: | C31: ANTECEDENTES DE RETIROS EN EXCESO (Detalle de saldos pendientes de imputación)
B32: RUT del beneficiario del retiro (titular o cesionario) | C32: Montos de retiros en exceso, reajustados ($)
B37: C34 | C37: C35
B39: CUADRO RESUMEN FINAL DE LA DECLARACION
B40: Cantidad de acciones al 31/12 | C40: MONTOS DE RETIROS, REMESAS O DIVIDENDOS REAJUSTADOS ($) | O40: CRÉDITOS PARA IMPUESTO GLOBAL COMPLEMENTARIO O ADICIONAL | AD40: Devolución de capital Art.17 N° 7 LIR. | AE40: Montos de retiros en exceso, reajustados ($) | AF40: Total de casos Informados
C41: Afectos a los Impuestos Global Complementario y/o Impuesto Adicional | G41: Rentas Exentas e Ingresos No Contitutivos de Renta (REX) | O41: Acumulados a Contar del 01.01.2017 | X41: Acumulados Hasta el 31.12.2016 | AC41: Crédito por impuesto tasa adicional, Ex. Art. 21 LIR.
G42: Rentas Con Tributación Cumplida | L42: Exentos de impuesto global complementario (IGC) y/o impuesto adicional (IA) | N42: Ingresos No Constitutivos de Renta | O42: Asociados a Rentas Afectas | U42: Asociados a Rentas Exentas | W42: Crédito por IPE | X42: Asociados a Rentas Afectas | Z42: Asociados a Rentas Exentas (artículo 11, Ley 18.401) | AB42: Crédito por IPE
G43: Rentas provenientes del registro RAP y Diferencia Inicial de sociedad acogida al ex Art. 14 TER A) LIR | H43: Otras rentas percibidas Sin Prioridad en su orden de imputación | I43: Exceso Distribuciones Desproporcionadas (N°9 Art.14 A) | J43: Utilidades afectadas con impuesto sustitutivo al FUT (ISFUT) Ley N°20.780 | K43: Rentas generadas hasta el 31.12.1983 y/o utilidades afectadas con impuesto sustitutivo al FUT (ISFUT) LEY N°21.210 | L43: Rentas Exentas de Impuesto Global Complementario (IGC) (Artículo 11, Ley 18.401), Afectas a Impuesto Adicional | M43: Rentas Exentas de Impuesto Global Complementario (IGC) y/o Impuesto Adicional (IA) | O43: No Sujetos a Restitución generados Hasta el 31.12.2019 | Q43: No Sujetos a Restitución generados a contar del 01.01.2020 | S43: Sujetos a Restitución | U43: Sujetos a Restitución | X43: Sin derecho a devolución | Y43: Con derecho a devolución | Z43: Sin derecho a devolución | AA43: Con derecho a devolución
C44: Con crédito por IDPC generados a contar del 01.01.2017 | D44: Con crédito por IDPC acumulados hasta el 31.12.2016 | E44: Con derecho a crédito por pago de IDPC voluntario | F44: Sin derecho a crédito | O44: Sin derecho a devolución | P44: Con derecho a devolución | Q44: Sin derecho a devolución | R44: Con derecho a devolución | S44: Sin derecho a devolución | T44: Con derecho a devolución | U44: Sin derecho a devolución | V44: Con derecho a devolución
B46: C36 | C46: C37 | D46: C38 | E46: C39 | F46: C40 | G46: C41 | H46: C42 | I46: C43 | J46: C44 | K46: C45 | L46: C46 | M46: C47 | N46: C48 | O46: C49 | P46: C50 | Q46: C51 | R46: C52 | S46: C53 | T46: C54 | U46: C55 | V46: C56 | W46: C57 | X46: C58 | Y46: C59 | Z46: C60 | AA46: C61 | AB46: C62 | AC46: C63 | AD46: C64 | AE46: C65 | AF46: C66
B49: DECLARO BAJO JURAMENTO QUE LOS DATOS CONTENIDOS EN EL PRESENTE DOCUMENTO SON LA EXPRESION FIEL DE LA VERDAD, POR LO QUE ASUMO LA RESPONSABILIDAD CORRESPONDIENTE
B51: RUT REPRESENTANTE LEGAL | F51: RUT DEL RESPONSABLE DE LA CONFECCIÓN DEL REGISTRO

Sheet Retiros
C2: 44938 | D2: 15640744-5 | E2: 400 | F2: Retiro socio felipe andres hiriart blome | G2: 2276374 | H2: 1.045 | I2: =+J2-G2 -> 102436.83 | J2: =+G2*H2 -> 2378810.8 | L2: =+G2*0.111111 -> 252930.19 | M2: =+J2*0.111111 -> 264312.05
C3: 44938 | D3: 16367300-2 | E3: 400 | F3: Retiro socio pedro jose lecaros sotomayor | G3: 2276374 | H3: 1.045 | I3: =+J3-G3 -> 102436.83 | J3: =+G3*H3 -> 2378810.8 | L3: =+G3*0.111111 -> 252930.19 | M3: =+J3*0.111111 -> 264312.05
C4: 44938 | D4: 15376982-6 | E4: 200 | F4: Retiro socio jorge alberto hiriart blome | G4: 1138187 | H4: 1.045 | I4: =+J4-G4 -> 51218.415 | J4: =+G4*H4 -> 1189405.4 | L4: =+G4*0.111111 -> 126465.1 | M4: =+J4*0.111111 -> 132156.03
C5: 44971 | D5: 15640744-5 | E5: 400 | F5: Retiro socio pedro jose lecaros sotomayor | G5: 258232 | H5: 1.037 | I5: =+J5-G5 -> 9554.584 | J5: =+G5*H5 -> 267786.58 | L5: =+G5*0.111111 -> 28692.416 | M5: =+J5*0.111111 -> 29754.035
C6: 44971 | D6: 16367300-2 | E6: 400 | F6: Retiro socio felipe andres hiriart blome | G6: 258232 | H6: 1.037 | I6: =+J6-G6 -> 9554.584 | J6: =+G6*H6 -> 267786.58 | L6: =+G6*0.111111 -> 28692.416 | M6: =+J6*0.111111 -> 29754.035
C7: 44971 | D7: 15376982-6 | E7: 200 | F7: Retiro socio jorge alberto hiriart blome | G7: 129116 | H7: 1.037 | I7: =+J7-G7 -> 4777.292 | J7: =+G7*H7 -> 133893.29 | L7: =+G7*0.111111 -> 14346.208 | M7: =+J7*0.111111 -> 14877.018
C8: 45054 | D8: 15640744-5 | E8: 400 | F8: Retiro socio pedro jose lecaros sotomayor | G8: 4000000 | H8: 1.023 | I8: =+J8-G8 -> 92000 | J8: =+G8*H8 -> 4092000 | L8: =+G8*0.111111 -> 444444 | M8: =+J8*0.111111 -> 454666.21
C9: 45054 | D9: 16367300-2 | E9: 400 | F9: Retiro socio felipe andres hiriart blome | G9: 4000000 | H9: 1.023 | I9: =+J9-G9 -> 92000 | J9: =+G9*H9 -> 4092000 | L9: =+G9*0.111111 -> 444444 | M9: =+J9*0.111111 -> 454666.21
C10: 45054 | D10: 15376982-6 | E10: 200 | F10: Retiro socio jorge alberto hiriart blome | G10: 2000000 | H10: 1.023 | I10: =+J10-G10 -> 46000 | J10: =+G10*H10 -> 2046000 | L10: =+G10*0.111111 -> 222222 | M10: =+J10*0.111111 -> 227333.11
C11: 45055 | D11: 15640744-5 | E11: 400 | F11: Retiro socio pedro jose lecaros sotomayor | G11: 1000000 | H11: 1.023 | I11: =+J11-G11 -> 23000 | J11: =+G11*H11 -> 1023000 | L11: =+G11*0.111111 -> 111111 | M11: =+J11*0.111111 -> 113666.55
C12: 45055 | D12: 16367300-2 | E12: 400 | F12: Retiro socio felipe andres hiriart blome | G12: 1000000 | H12: 1.023 | I12: =+J12-G12 -> 23000 | J12: =+G12*H12 -> 1023000 | L12: =+G12*0.111111 -> 111111 | M12: =+J12*0.111111 -> 113666.55
C13: 45055 | D13: 15376982-6 | E13: 200 | F13: Retiro socio jorge alberto hiriart blome | G13: 500000 | H13: 1.023 | I13: =+J13-G13 -> 11500 | J13: =+G13*H13 -> 511500 | L13: =+G13*0.111111 -> 55555.5 | M13: =+J13*0.111111 -> 56833.276
... C34: 45202 | D34: 15376982-6 | E34: 200 | F34: Retiro socio jorge alberto hiriart blome | G34: 2250000 | H34: 1.012 | I34: =+J34-G34 -> 27000 | J34: =+G34*H34 -> 2277000 | L34: =+G34*0.111111 -> 249999.75 | M34: =+J34*0.111111 -> 252999.75
C35: 45264 | F35: Retiro socio pedro jose lecaros sotomayor | G35: 4500000 | H35: 1 | I35: =+J35-G35 -> 0 | J35: =+G35*H35 -> 4500000 | L35: =+G35*0.111111 -> 499999.5 | M35: =+J35*0.111111 -> 499999.5
C36: 45264 | F36: Retiro socio felipe andres hiriart blome | G36: 4500000 | H36: 1 | I36: =+J36-G36 -> 0 | J36: =+G36*H36 -> 4500000 | L36: =+G36*0.111111 -> 499999.5 | M36: =+J36*0.111111 -> 499999.5
C37: 45264 | F37: Retiro socio jorge alberto hiriart blome | G37: 2250000 | H37: 1 | I37: =+J37-G37 -> 0 | J37: =+G37*H37 -> 2250000 | L37: =+G37*0.111111 -> 249999.75 | M37: =+J37*0.111111 -> 249999.75
G38: =SUM(G2:G37) -> 82586515 | I38: =SUM(I2:I37) -> 1558728.5 | J38: =SUM(J2:J37) -> 84145244 | L38: =SUM(L2:L37) -> 9176270.3 | M38: =SUM(M2:M37) -> 9349462.2
C41: 45291 | D41: 15640744-5 | E41: 400 | F41: Retiro socio pedro jose lecaros sotomayor | G41: =+G38*40% -> 33034606 | L41: =+G41*0.111111 -> 3670508.1
C42: 45291 | D42: 16367300-2 | E42: 400 | F42: Retiro socio felipe andres hiriart blome | G42: =+G41 -> 33034606 | L42: =+G42*0.111111 -> 3670508.1
C43: 45291 | D43: 15376982-6 | E43: 200 | F43: Retiro socio jorge alberto hiriart blome | G43: =+G38-G41-G42 -> 16517303 | L43: =+G43*0.111111 -> 1835254.1

Sheet RRE 2023
F1: REX (INR)
B2: Detalle | D2: Control | E2: Rentas Afectas a Impuesto (RAI) | F2: Rentas con tributacion Cumplida RAP | G2: REX por rentas que pagaron el IUS LEY 20.780 | I2: Saldo Acumulado de Créditos (SAC) (4) | R2: Saldo total de utilidades tributarias (STUT)
I3: Acumulados a contar del 01.01.2017 | N3: Acumulados hasta el 31.12.2016
I4: Tasa de crédito vigente 10% | L4: 0.111111 | M4: CTD contra impuestos finales (Arts. 41 A) y 41 C) de la LIR) | N4: Tasa Efectiva | O4: =TRUNC(N8/R8,6) -> #DIV/0! | P4: 0.08
I5: No Sujetos a Restitución | K5: Sujetos a Restitución | O5: =ROUND(+O4/(1+O4),3) -> #DIV/0! | P5: CTD contra impuestos finales (Arts. 41 A) y 41 C) de la LIR)
A6: Código DJ 1939 | I6: Sin Derecho a Devolución | J6: Con Derecho a Devolución | K6: Sin Derecho a Devolución | L6: Con Derecho a Devolución | N6: Con Derecho a Devolución | O6: Sin Derecho a Devolución
A8: 100 | B8: Saldos de aperturas nuevos registros al 01.01.2023 | D8: =SUM(E8:G8) -> 533941272 | E8: 533941272 | F8: 0 | G8: 0 | I8: 0 | J8: 15201324 | K8: 0 | L8: 0 | M8: 0 | N8: 0 | O8: 0 | P8: 0 | R8: 0
A9: 101
B10: Remanente anterior reajustado… | D10: =+D8+D9 -> 533941272 | E10: =+E8+E9 -> 533941272 | F10: =+F8+F9 -> 0 | G10: =+G8+G9 -> 0 | I10: =+I8+I9 -> 0 | J10: =+J8+J9 -> 15201324 | K10: =+K8+K9 -> 0 | L10: =+L8+L9 -> 0 | M10: =+M8+M9 -> 0 | N10: =+N8+N9 -> 0 | O10: =+O8+O9 -> 0 | P10: =+P8+P9 -> 0 | R10: =+R8+R9 -> 0
A12: 103 | B12: Si saldo de RAI es positivo reversar | D12: =SUM(E12) -> -533941272 | E12: =-E10 -> -533941272
A14: 105 | B14: Nuevo RAI al 31.12.2023 | D14: =SUM(E14:G14) -> 286828048 | E14: =+D40 -> 286828048
B15: Nuevo DDAN | D15: =SUM(E15:G15) -> 0
B16: Nuevo REX: | D16: =SUM(E16:G16) -> 0
A18: 108 | B18: Crédito 1era Categoría RLI determinada año 2023 | D18: =SUM(E18:G18) -> 0 | J18: 0
B20: SALDO ANTES DE IMPUTACIONES DE RETIROS | D20: =SUM(D10:D19) -> 286828048 | E20: =SUM(E10:E19) -> 286828048 | F20: =SUM(F10:F19) -> 0 | G20: =SUM(G10:G19) -> 0 | I20: =SUM(I10:I19) -> 0 | J20: =SUM(J10:J19) -> 15201324 | K20: =SUM(K10:K19) -> 0 | L20: =SUM(L10:L19) -> 0 | M20: =SUM(M10:M19) -> 0 | N20: =SUM(N10:N19) -> 0 | O20: =SUM(O10:O19) -> 0 | P20: =SUM(P10:P19) -> 0 | R20: =SUM(R10:R19) -> 0
B23: RETIROS SOCIOS | D23: =SUM(E23:G23) -> -82586515 | E23: =-Retiros!G38 -> -82586515 | J23: =+E23*L4 -> -9176270.3
A25: 111 | B25: Crédito inc 1° artí. 21 no afectados con 40% (reajust) | D25: =SUM(E25:G25) -> 0
A26: 111 | B26: Credito inc 2° arí. 21. (gasto reajustado) | D26: =SUM(E26:G26) -> 0 | J26: =-C26*L4 -> 0
B29: Saldos al 31.12.2023 | D29: =SUM(D20:D28) -> 204241533 | E29: =SUM(E20:E28) -> 204241533 | F29: =SUM(F20:F28) -> 0 | G29: =SUM(G20:G28) -> 0 | I29: =SUM(I20:I28) -> 0 | J29: =SUM(J20:J28) -> 6025053.7 | K29: =SUM(K20:K28) -> 0 | L29: =SUM(L20:L28) -> 0 | M29: =SUM(M20:M28) -> 0 | N29: =SUM(N20:N28) -> 0 | O29: =SUM(O20:O28) -> 0 | P29: =SUM(P20:P28) -> 0 | R29: =SUM(R20:R28) -> 0
B32: Calculo del RAI Final
B34: CPT al 31.12.2023 | D34: =+'CPT 2023'!F26 -> 204341533
B35: Más:
B36: Dividendos pagados historicos | D36: =+Retiros!G38 -> 82586515
B37: Menos:
B38: REX
B39: Capital | D39: =-'Balance 2023'!H19 -> -100000
B40: RAI al 31.12.2023 | D40: =SUM(D34:D39) -> 286828048
B47: CAPITAL SOCIAL INICIAL | C47: ConstitucionSoc.
B48: 100000 | C48: 44075

Sheet CPT 2023
B1: CERTIFICADO DE CAPITAL PROPIO INICIAL
B4: TREGUALEMU SPA
B5: RUT: 77.213.284-0
B9: TOTAL ACTIVO | F9: =+'Balance 2023'!G30 -> 293967871
B11: Menos | F11: =SUM(E13) -> -82586515
B13: Dividendos Distribuidos | E13: =-'Balance 2023'!G14 -> -82586515
B15: TOTAL ACTIVO DEPURADO | F15: =SUM(F9:F13) -> 211381356
B17: PASIVO EXIGIBLE | F17: =SUM(E18:E23) -> -7039823
B18: Total Pasivo | E18: =-'Balance 2023'!H30 -> -308938472
B19: Menos
B21: Capital Pagado | E21: =+'Balance 2023'!H19 -> 100000
B22: Utilidad acumulada | E22: =+'Balance 2023'!H21 -> 301798649
B26: CAPITAL PROPIO INICIAL AL 01 DE ENERO DE 2024 | F26: =SUM(F15:F25) -> 204341533
B30: RAZONABILIDAD DEL PATRIMONIO
F31: según CLIENTE
B32: CPT INICIAL F22 AT 2023 | D32: 533941272 | F32: 275789929
F33: =+D32-F32 -> 258151343
B34: Multas | D34: =-'RLI 2023'!D12 -> -626743
B35: IMPTO PAGADO | D35: =-'RLI 2023'!D13 -> -13554622
B36: Reajuste art 72 | D36: =-'RLI 2023'!D14 -> -280973
B37: RLI | D37: =+'RLI 2023'!E23 -> -508263
B38: Pérdida de arrastre | D38: 0
B39: 50% RLI reinvertida | D39: 0
B40: Retiros | D40: =-Retiros!G38 -> -82586515
B41: Otros ajustes año anterior | D41: -232042623
B42: TOTAL | D42: =SUM(D32:D41) -> 204341533
C44: DIFF | D44: =+F26-D42 -> 0
B59: CM CAPITAL | D59: IPC | E59: CM | F59: ACTUALIZADO
B60: 500000 | C60: 42572 | D60: 0.008 | E60: =+B60*D60 -> 4000 | F60: =+B60+E60 -> 504000
C61: 2017 | D61: 0.019 | E61: =+F60*D61 -> 9576 | F61: =+F60+E61 -> 513576
C62: 2018 | D62: 0.028 | E62: =+F61*D62 -> 14380.128 | F62: =+F61+E62 -> 527956.13
C63: 2019 | D63: 0.028 | E63: =+F62*D63 -> 14782.772 | F63: =+F62+E63 -> 542738.9

Sheet RLI 2023
B1: TREGUALEMU SPA | E1: 14 D 3
B2: RUT: 77.213.284-0
B4: DETERMINACIÓN DEL RESULTADO TRIBUTARIO DE PRIMERA CATEGORÍA AL 31 DE DICIEMBRE DE 2023
E6: $
B7: Resultado Financiero al 31.12.2023 | E7: =-'Balance 2023'!J31 -> -14970601
B9: Se agrega: | E9: =SUM(D10:D14) -> 14462338
B11: Ajuste tributario FFMM | D11: 0
B12: Multa SII | D12: =+'Balance 2023'!I26 -> 626743
B13: Impuesto de Primera Categoría | D13: =+'Balance 2023'!I28 -> 13554622
B14: Reajuste Art 72 | D14: =+'Balance 2023'!I29 -> 280973
B16: Se deduce: | E16: =SUM(D17:D18) -> 0
B17: Ajuste financiero FFMM
B18: Pérdida Tributaria $
B20: Se desagrega: | E20: =SUM(D21) -> 0
B21: Gastos Rechazados afectos al artículo 21 (actualizados)
B23: RENTA LIQUIDA O (PERDIDA TRIBUTARIA) AL 31.12.2023 | E23: =SUM(E7:E22) -> -508263
B25: Rebaja RLI 14 E) | E25: =-I31 -> 0 | H25: CALCULO 14 E)
H26: RLI | I26: =+E23 -> -508263
B27: Nueva RLI | E27: =+E23+E25 -> -508263 | H27: RETIROS
H28: IDPC | I28: =-D13-D14 -> -13835595
B29: Impuesto a la renta 1° categoría determinado 10% | E29: =IF(E27>0,E27*10%,0) -> 0 | H29: Multas | I29: =-D12 -> -626743
H30: RLI REINVERTIDA | I30: =SUM(I26:I29) -> -14970601
B31: Impuesto Unico artículo 21 inciso 3, sobre gastos rechazados afectos | E31: =-D21*35% -> 0 | H31: 0.5 | I31: =IF(I30>0,I30*0.5,0) -> 0
B33: Menos
B34: PPM Actualizados | E34: 0
B36: Total impuesto a pagar (devolución) | E36: =SUM(E29:E34) -> 0
D37: Reajuste art 72 | E37: =+E36*0 -> 0
D38: A pagar | E38: =+E36+E37 -> 0

Sheet Balance 2023
A2: BALANCE DESDE 01-01-2023 A 31-12-2023
A3: 77.213.284-0 TREGUALEMU SPA | L3: =A3 -> 77.213.284-0 TREGUALEMU SPA
C4: SUMAS | E4: SALDOS | G4: INVENTARIO | I4: RESULTADO
B5: Cuenta | C5: Debitos | D5: Creditos | E5: Deudor | F5: Acreedor | G5: Activo | H5: Pasivo | I5: Perdidas | J5: Ganancias
B6: 1101-01 CUENTA CAJA | C6: 593571 | D6: 0 | E6: 593571 | F6: 0 | G6: 593571 | H6: 0 | I6: 0 | J6: 0
B7: 1101-04 BANCO SANTANDER | C7: 74541665 | D7: 74383356 | E7: 158309 | F7: 0 | G7: 158309 | H7: 0 | I7: 0 | J7: 0
B8: 1103-02 ACCIONES POR SUSCRIBIR | C8: 100000 | D8: 100000 | E8: 0 | F8: 0 | G8: 0 | H8: 0 | I8: 0 | J8: 0
B9: 1106-02-0001 CUENTA POR COBRAR JORGE ALBERTO HIRIART BLOME | C9: 19948641 | D9: 16517303 | E9: 3431338 | F9: 0 | G9: 3431338 | H9: 0 | I9: 0 | J9: 0
B10: 1106-02-0004 CTA CTE ECOX SPA | C10: 242712837 | D10: 73575001 | E10: 169137836 | F10: 0 | G10: 169137836 | H10: 0 | I10: 0 | J10: 0
B11: 1106-02-0009 CTA CTE INVERSIONES AYSEN SPA | C11: 38060302 | D11: 0 | E11: 38060302 | F11: 0 | G11: 38060302 | H11: 0 | I11: 0 | J11: 0
B12: 1108-01 PAGOS PROVISIONALES | C12: 174957 | D12: 174957 | E12: 0 | F12: 0 | G12: 0 | H12: 0 | I12: 0 | J12: 0
B13: 1108-02 IVA CREDITO FISCAL | C13: 12569 | D13: 12569 | E13: 0 | F13: 0 | G13: 0 | H13: 0 | I13: 0 | J13: 0
B14: 1111-04 DIVIDENDOS DISTRIBUIDOS | C14: 192024015 | D14: 109437500 | E14: 82586515 | F14: 0 | G14: 82586515 | H14: 0 | I14: 0 | J14: 0
B15: 2105-04 HONORARIOS POR PAGAR | C15: 40000 | D15: 40000 | E15: 0 | F15: 0 | G15: 0 | H15: 0 | I15: 0 | J15: 0
B16: 2112-01-0004 CTA CTE ECOX SPA | C16: 14287381 | D16: 14287381 | E16: 0 | F16: 0 | G16: 0 | H16: 0 | I16: 0 | J16: 0 | K16: =+'Balance 2023'!$H16-G17 -> 0
B17: 2112-01-0005 CTA CTE FELIPE ANDRES HIRIART BLOME | C17: 7247558 | D17: 14287381 | E17: 0 | F17: 7039823 | G17: 0 | H17: 7039823 | I17: 0 | J17: 0
B18: 2116-01 FACTURAS POR PAGAR | C18: 456263 | D18: 456263 | E18: 0 | F18: 0 | G18: 0 | H18: 0 | I18: 0 | J18: 0
B19: 2301-01 C A P I T A L | C19: 0 | D19: 100000 | E19: 0 | F19: 100000 | G19: 0 | H19: 100000 | I19: 0 | J19: 0
B20: 2305-05 UTILIDAD (PERDIDA) EJERC. | C20: 135153930 | D20: 135153930 | E20: 0 | F20: 0 | G20: 0 | H20: 0 | I20: 0 | J20: 0
B21: 2305-06 UTILIDADES ACUMULADAS | C21: 0 | D21: 301798649 | E21: 0 | F21: 301798649 | G21: 0 | H21: 301798649 | I21: 0 | J21: 0
B22: 4101-07 SERVICIOS PAGADOS | C22: 357211 | D22: 0 | E22: 357211 | F22: 0 | G22: 0 | H22: 0 | I22: 357211 | J22: 0
B23: 4101-13 GASTOS OPERACIONALES | C23: 12000 | D23: 0 | E23: 12000 | F23: 0 | G23: 0 | H23: 0 | I23: 12000 | J23: 0
B24: 4201-02 HONORARIOS PROFESIONALES | C24: 40000 | D24: 0 | E24: 40000 | F24: 0 | G24: 0 | H24: 0 | I24: 40000 | J24: 0
B25: 4201-10 GASTOS BANCARIOS | C25: 86483 | D25: 0 | E25: 86483 | F25: 0 | G25: 0 | H25: 0 | I25: 86483 | J25: 0
B26: 4201-11 INTERESES Y MULTAS | C26: 626743 | D26: 0 | E26: 626743 | F26: 0 | G26: 0 | H26: 0 | I26: 626743 | J26: 0
B27: 4201-73 IVA NO RECUPERABLE | C27: 12569 | D27: 0 | E27: 12569 | F27: 0 | G27: 0 | H27: 0 | I27: 12569 | J27: 0
B28: 4701-01 IMPTO PRIMERA CATEGORIA | C28: 13554622 | D28: 0 | E28: 13554622 | F28: 0 | G28: 0 | H28: 0 | I28: 13554622 | J28: 0
B29: 4701-02 REAJUSTE IMPUESTO PRIMERA CAT | C29: 280973 | D29: 0 | E29: 280973 | F29: 0 | G29: 0 | H29: 0 | I29: 280973 | J29: 0
B30: Sumas | C30: =SUM('Balance 2023'!$C$6:$C$29) -> 740324290 | D30: =SUM('Balance 2023'!$D$6:$D$29) -> 740324290 | E30: =SUM('Balance 2023'!$E$6:$E$29) -> 308938472 | F30: =SUM('Balance 2023'!$F$6:$F$29) -> 308938472 | G30: =SUM('Balance 2023'!$G$6:$G$29) -> 293967871 | H30: =SUM('Balance 2023'!$H$6:$H$29) -> 308938472 | I30: =SUM('Balance 2023'!$I$6:$I$29) -> 14970601 | J30: =SUM('Balance 2023'!$J$6:$J$29) -> 0
B31: =IF(H31="","Perdida Ejercicio","Ganancia Ejercicio") -> Perdida Ejercicio | G31: =IF(G30<H30,H30-G30,"") -> 14970601 | H31: =IF(G30>H30,G30-H30,"") | I31: =IF(I30<J30,J30-I30,"") | J31: =IF(I30>J30,I30-J30,"") -> 14970601
B32: Totales | C32: =SUM(C30:C31) -> 740324290 | D32: =SUM(D30:D31) -> 740324290 | E32: =SUM(E30:E31) -> 308938472 | F32: =SUM(F30:F31) -> 308938472 | G32: =SUM(G30:G31) -> 308938472 | H32: =SUM(H30:H31) -> 308938472 | I32: =SUM(I30:I31) -> 14970601 | J32: =SUM(J30:J31) -> 14970601

Sheet F-22
AM1: Oandana
O2: AÑO TRIBUTARIO 2024 IMPUESTOS ANUALES A LA RENTA | AE2: Instrucciones:
AE3: https://www.sii.cl/servicios_online/renta/2024/rentaform.html
D5: TIPOS DE RENTAS Y REBAJAS | N5: CRÉDITO POR IMPUESTO DE PRIMERA CATEGORÍA | AH5: RENTAS Y REBAJAS
N6: CON OBLIGACIÓN DE RESTITUCIÓN | X6: SIN OBLIGACIÓN DE RESTITUCIÓN
N7: Sin derecho a devolución | S7: Con derecho a devolución | X7: Sin derecho a devolución | AC7: Con derecho a devolución
B8: Rentas brutas afectas | C8: Rentas afectas de fuente nacional o extranjera | D8: 1 | E8: Retiros o remesas afectos al IGC o IA, según art. 14 letras A) y/o D) N° 3 LIR | N8: 1592 | S8: 1024 | X8: 1593 | AC8: 1025 | AH8: 104 | AM8: +
D9: 2 | E9: Dividendos afectos al IGC o IA, según art.14 letras A) y/o D) N° 3 LIR | N9: 1594 | S9: 1026 | X9: 1595 | AC9: 1027 | AH9: 105 | AM9: +
D10: 3 | E10: Gastos rechazados y otras partidas referidos en el art. 21 inc. 3° LIR | AH10: 106 | AM10: +
D11: 4 | E11: Rentas presuntas propias y/o de terceros, según art. 14 letra B) N° 2 y art. 34 LIR | AC11: 603 | AH11: 108 | AM11: +
D12: 5 | E12: Rentas propias y/o de terceros, provenientes de empresas que determinan su renta efectiva sinCcontabilidad completa, según art. 14 letra B) N° 1 LIR | N12: 1721 | O12: =+$O$15+$O$16 -> 0 | S12: 1722 | T12: =+$T$15+$T$16 -> 0 | X12: 1596 | Y12: =+$Y$13+$Y$14+$Y$15+$Y$16+$Y$18 -> 0 | AC12: 954 | AD12: =+SUM(AD13:$AG$18) -> 0 | AH12: 955 | AI12: =+SUM($AI$13:$AL$18) -> 0 | AM12: +
E13: a) Rentas del arrendamiento, subarrendamiento, usufructo o cesión de cualquier otra forma del uso o goce temporal de bienes raíces agrícolas y no agrícolas, determinadas mediante el respectivo contrato | X13: 1917 | AC13: 1848 | AH13: 1849
E14: b) Rentas por participaciones o cuotas de comunidad obtenidas por la empresa que determina su renta efectiva sin contabilidad completa | X14: 1850 | AC14: 1851 | AH14: 1852
E15: c) Rentas por participaciones o cuotas de comunidad obtenida por la empresa que determinan su renta efectiva sin contabilidad completa, provenientes de otras empresas en las que participa | N15: 1853 | S15: 1854 | X15: 1855 | AC15: 1856 | AH15: 1857
E16: d) Rentas efectivas de terceros obtenidas por empresas acogidas al régimen de renta presunta | N16: 1858 | S16: 1859 | X16: 1860 | AC16: 1861 | AH16: 1862
E17: e) Rentas esporádicas | AC17: 1872 | AH17: 1873
E18: f) Otras rentas propias y/o de terceros | X18: 1863 | AC18: 1864 | AH18: 1865
D19: 6 | E19: Rentas asignada propias y/o de terceros, provenientes de empresas sujetas al art. 14 letra D) N° 8 LIR | N19: 1597 | S19: 1598 | X19: 1599 | AC19: 1631 | AH19: 1632 | AM19: +
D20: 7 | E20: Rentas percibidas de los arts. 42 Nº 2 (honorarios) y 48 (rem. directores S.A.) LIR, según Recuadro N° 1 | AH20: 110 | AM20: +
D21: 8 | E21: Rentas de capitales mobiliarios (art. 20 N° 2 LIR), mayor valor en la enajenación o rescate de cuotas fondos mutuos y fondos de inversión y enajenación de acciones y derechos sociales (art. 17 N° 8 LIR) y retiros de ELD (arts. 42 ter y quáter LIR) | AC21: 605 | AD21: =+$AD$22 | AH21: 155 | AI21: =+SUM(AI22:$AL$24) -> 0 | AM21: +
E22: a) Rentas de capitales mobiliarios (art. 20 N° 2 LIR) | AC22: 1866 | AH22: 1867
E23: b) Mayor valor obtenido en la enajenación o rescate de cuotas fondos mutuos y fondos de inversión y en la enajenación de acciones y derechos sociales (art. 17 N° 8 LIR) | AH23: 1869
E24: c) Retiros de ELD (arts. 42 ter y quáter LIR) | AH24: 1871
D25: 9 | E25: Rentas exentas del IGC, según art. 54 N° 3 LIR | N25: 1633 | O25: =+$O$26+$O$27+$O$29 -> 0 | S25: 1105 | T25: =+$T$26+$T$27+$T$29 -> 0 | X25: 1634 | Y25: =+$Y$26+$Y$27+$Y$29 -> 0 | AC25: 606 | AD25: =+$AD$26+$AD$27+$AD$29 -> 0 | AH25: 152 | AI25: =+SUM(AI26:$AL$29) -> 0 | AM25: +
E26: a) Rentas de FCH provenientes de capitales mobiliarios, que no excedan los límites de 20 o 30 UTM, según corresponda. | N26: 1874 | S26: 1875 | X26: 1876 | AC26: 1877 | AH26: 1878
E27: b) Retiros y/o dividendos informados por las empresas y sociedades administradoras de FI y FM | N27: 1879 | S27: 1880 | X27: 1881 | AC27: 1882 | AH27: 1883
E28: c) Retiros de ELD del art. 42 ter LIR efectuados durante el año 2023, que no excedan los límites exentos de impuesto de 200 u 800 UTM | AH28: 1884
E29: d) Otras Rentas exentas del IGC, según art. 54 N° 3 LIR | N29: 1885 | S29: 1886 | X29: 1887 | AC29: 1888 | AH29: 1889
D30: 10 | E30: Otras rentas de fuente chilena afectas al IGC o IA (según instrucciones) | X30: 1635 | AC30: 1031 | AH30: 1032 | AM30: +
D31: 11 | E31: Mayor valor en la enajenación de bienes raíces situados en Chile | AC31: 1890 | AH31: 1891 | AM31: +
D32: 12 | E32: Otras rentas de fuente extranjera afectas al IGC o IA (según instrucciones) | AC32: 1914 | AH32: 1104 | AM32: +
D33: 13 | E33: Sueldos, pensiones y otras rentas similares de fuente nacional | N33: 1098 | S33: Sueldos, pensiones y otras rentas similares de fuente extranjera | AC33: 1030 | AH33: 161 | AI33: =+$O$33+$AD$33 -> 0 | AM33: +
D34: 14 | E34: Incremento por IDPC, según arts. 54 N° 1 y 62 LIR | N34: 159 | S34: Incremento por impuestos soportados en el exterior, según arts. 41 A LIR | AC34: 748 | AH34: 749 | AI34: =+$O$34+AD34 -> 0 | AM34: +
C35: Rebajas a la renta | D35: 15 | E35: Impuesto Territorial pagado en el año 2023, según art. 55 letra a) LIR | AH35: 166 | AM35: -
D36: 16 | E36: Donaciones, según art. 7° Ley N° 16.282 y D.L. N° 45 de 1973 | AH36: 907 | AM36: -
D37: 17 | E37: Pérdida en operaciones de capitales mobiliarios y ganancias de capital según códigos 105, 155,152 ,1032, 1891, y 1104 (arts. 54 N° 1 y 62 LIR) | AH37: 169 | AM37: -
D38: 18 | E38: Rebaja por donaciones a entidades sin fines de lucro según nuevo Título VIII bis D.L. N° 3.063 de 1979 (incorporado por Ley N° 21.440), efectuadas por contribuyentes del IUSC, IGC o IA | AH38: 1833 | AM38: -
D39: 19 | E39: SUB TOTAL (Si declara IA trasladar a código 133 o 32) | AH39: 158 | AI39: =+($AI$8+$AI$9+$AI$10+$AI$11+$AI$12+$AI$19+$AI$20+$AI$21+$AI$25)+SUM($AI$30:$AL$34)-SUM($AI$35:$AL$38) -> 0 | AM39: =
D40: 20 | E40: Cotizaciones previsionales correspondientes al empresario o socio, según art. 55 letra b) LIR | AH40: 111 | AM40: -
D41: 21 | E41: Intereses pagados por créditos con garantía hipotecaria, según art. 55 bis LIR | N41: 750 | S41: Dividendos hipotecarios pagados por viviendas nuevas acogidas al D.F.L. N° 2 de 1959, según Ley N° 19.622 | AC41: 740 | AH41: 751 | AI41: =+$O$41+$AD$41 -> 0 | AM41: -
...

Sheet Mayor 2023
A2: LIBRO MAYOR DESDE 01-01-2023 A 31-12-2023
A3: ='Balance 2023'!L3 -> 77.213.284-0 TREGUALEMU SPA
B7: Cuenta
C8: Comprobante | G8: $ Monto
A9: Cta | B9: Fecha | C9: Tipo | D9: N | E9: S | F9: Glosa | G9: Debe | H9: Haber | I9: Saldo
A10: 1101-01 CUENTA CAJA | B10: 44927 | C10: Traspaso | D10: 1 | E10: 1 | F10: Reapertura comercial año 2023 | G10: 493571 | H10: 0 | I10: 493571
A11: 1101-01 CUENTA CAJA | B11: 45291 | C11: Ingreso | D11: 29 | E11: 2 | F11: Cancela acciones por suscribir | G11: 100000 | H11: 0 | I11: 593571
A12: 1103-02 ACCIONES POR SUSCRIBIR | B12: 44927 | C12: Traspaso | D12: 1 | E12: 5 | F12: Reapertura comercial año 2023 | G12: 100000 | H12: 0 | I12: 100000
A13: 1103-02 ACCIONES POR SUSCRIBIR | B13: 45291 | C13: Ingreso | D13: 29 | E13: 1 | F13: Cancela acciones por suscribir | G13: 0 | H13: 100000 | I13: 0
A14: 1108-01 PAGOS PROVISIONALES | B14: 44927 | C14: Traspaso | D14: 1 | E14: 6 | F14: Reapertura comercial año 2023 | G14: 174957 | H14: 0 | I14: 174957
A15: 1108-01 PAGOS PROVISIONALES | B15: 45049 | C15: Egreso | D15: 42 | E15: 2 | F15: Ecox paga el impuesto a la renta de tregualemu | G15: 0 | H15: 174957 | I15: 0
A16: 1108-02 IVA CREDITO FISCAL | B16: 44957 | C16: Traspaso | D16: 2 | E16: 0 | F16: Centralización compras enero 2023 - iva crédito fiscal | G16: 1268 | H16: 0 | I16: 1268
A17: 1108-02 IVA CREDITO FISCAL | B17: 44985 | C17: Traspaso | D17: 3 | E17: 0 | F17: Centralización compras febrero 2023 - iva crédito fiscal | G17: 850 | H17: 0 | I17: 2118
A18: 1108-02 IVA CREDITO FISCAL | B18: 45016 | C18: Traspaso | D18: 4 | E18: 0 | F18: Centralización compras marzo 2023 - iva crédito fiscal | G18: 1304 | H18: 0 | I18: 3422
A19: 1108-02 IVA CREDITO FISCAL | B19: 45046 | C19: Traspaso | D19: 5 | E19: 0 | F19: Centralización compras abril 2023 - iva crédito fiscal | G19: 1308 | H19: 0 | I19: 4730
A20: 1108-02 IVA CREDITO FISCAL | B20: 45077 | C20: Traspaso | D20: 6 | E20: 0 | F20: Centralización compras mayo 2023 - iva crédito fiscal | G20: 1294 | H20: 0 | I20: 6024
A21: 1108-02 IVA CREDITO FISCAL | B21: 45107 | C21: Traspaso | D21: 7 | E21: 0 | F21: Centralización compras junio 2023 - iva crédito fiscal | G21: 868 | H21: 0 | I21: 6892
... A205: 1106-02-0009 CTA CTE INVERSIONES AYSEN SPA | B205: 44927 | C205: Traspaso | D205: 1 | E205: 4 | F205: Reapertura comercial año 2023 | G205: 38060302 | H205: 0 | I205: 38060302
